#VRML_SIM R2023b utf8

EXTERNPROTO "https://raw.githubusercontent.com/cyberbotics/webots/R2023b/projects/objects/backgrounds/protos/TexturedBackground.proto"
EXTERNPROTO "https://raw.githubusercontent.com/cyberbotics/webots/R2023b/projects/objects/backgrounds/protos/TexturedBackgroundLight.proto"
EXTERNPROTO "https://raw.githubusercontent.com/cyberbotics/webots/R2023b/projects/objects/floors/protos/RectangleArena.proto"

WorldInfo {
}
Viewpoint {
  orientation -0.1505015812165766 0.15335265649310698 0.9766433518935237 1.5756822102818848
  position -0.06314087804512791 -1.1163392664512242 0.5784497422636949
}
TexturedBackground {
}
TexturedBackgroundLight {
}
RectangleArena {
}
Robot {
  translation -0.0005422801236218359 0.0033664922342425503 0.10064497042507979
  rotation 0.3033870117204683 -0.16489753696552636 -0.9384908755134634 0.0083178382419243
  children [
    DEF THUMP HingeJoint {
      jointParameters HingeJointParameters {
        position 6.215928968381861e-05
        axis 0 1 0
        anchor 0.07 0 0.12
      }
      device [
        RotationalMotor {
          name "thump"
        }
      ]
      endPoint Solid {
        translation 0.06499834330173665 0.023000000000000003 0.10300031086658581
        rotation -2.0922145915377953e-06 0.9999999999673194 7.809219254254549e-06 0.5236674664692608
        children [
          DEF PHALANX_13 HingeJoint {
            jointParameters HingeJointParameters {
              position 3.616105413200171e-05
              axis 0 1 0
              anchor 0.004 0.11 0.004
            }
            device [
              RotationalMotor {
                name "phalanx13"
              }
            ]
            endPoint Solid {
              translation -0.022399171894599904 -0.00039999999999977554 0.026900954636856586
              rotation 0.25164774253210886 -0.2595288852680236 -0.932372335169824 1.631415922054575
              children [
                DEF PHALANX_14 HingeJoint {
                  jointParameters HingeJointParameters {
                    position 0.00013301004935202187
                    axis -1 0 0
                    anchor 1 -0.01 0.01
                  }
                  device [
                    RotationalMotor {
                      name "phalanx14"
                    }
                  ]
                  endPoint Solid {
                    translation -4.123659995691753e-07 -0.036999068690819675 0.01700359120940106
                    rotation 0.99999999997445 -3.385787085549693e-06 -6.295762376480249e-06 1.648006989950649
                    children [
                      DEF PHALANX_15 HingeJoint {
                        jointParameters HingeJointParameters {
                          position -2.1095925599241821e-07
                          axis -1 0 0
                          anchor 1 -0.015 0.01
                        }
                        device [
                          RotationalMotor {
                            name "phalanx15"
                          }
                        ]
                        endPoint Solid {
                          translation 2.511690022632962e-08 -0.028275102863919335 0.023575697199494552
                          rotation 0.9999999999999769 -5.7883216188019926e-08 2.070409736830613e-07 1.6481502109592758
                          children [
                            DEF FORM Shape {
                              appearance PBRAppearance {
                                metalness 0
                              }
                              geometry Box {
                                size 0.02 0.02 0.033
                              }
                            }
                          ]
                          boundingObject USE FORM
                          physics Physics {
                          }
                          linearVelocity 8.949487623848159e-08 2.8416196480132896e-07 -4.6853927821730843e-07
                          angularVelocity -1.2503501148300493e-06 -9.19134813122894e-06 2.1484803899578296e-08
                        }
                      }
                      DEF FORM Shape {
                        appearance PBRAppearance {
                          metalness 0
                        }
                        geometry Box {
                          size 0.02 0.02 0.055
                        }
                      }
                    ]
                    boundingObject USE FORM
                    physics Physics {
                    }
                    linearVelocity -1.5510913452482812e-07 3.2243632676241884e-07 -2.9059884854021704e-07
                    angularVelocity -1.2550277244018045e-06 -7.0893165947340725e-06 1.5108741972585286e-08
                  }
                }
                DEF FORM Shape {
                  appearance PBRAppearance {
                    metalness 0
                  }
                  geometry Box {
                    size 0.02 0.02 0.059
                  }
                }
              ]
              name "solid(4)"
              boundingObject USE FORM
              physics Physics {
              }
              linearVelocity -9.319869839184523e-08 3.0186190856206593e-07 -7.566913634288844e-08
              angularVelocity -1.2676818109133078e-06 -1.4412681874788883e-06 -2.034109183399593e-09
            }
          }
          DEF FORM Shape {
            appearance PBRAppearance {
              metalness 0
            }
            geometry Box {
              size 0.02 0.02 0.04
            }
          }
        ]
        name "solid(5)"
        boundingObject USE FORM
        physics Physics {
        }
        linearVelocity -4.5347989338246226e-08 2.5813231793158837e-07 -5.348105525104107e-08
        angularVelocity -1.2586398916085397e-06 -1.8087168554829012e-07 1.1513443054147346e-09
      }
    }
    DEF PHALANX_1 HingeJoint {
      jointParameters HingeJointParameters {
        position 0.0001250766290086247
        axis -1 0 0
        anchor -0.002 0.14 0.11
      }
      device [
        RotationalMotor {
          name "phalanx1"
        }
      ]
      endPoint Solid {
        translation -0.05999999999999999 0.13216775174711703 0.13200097980329994
        rotation -1 0 0 0.00012507662972447277
        children [
          DEF PHALANX_2 HingeJoint {
            jointParameters HingeJointParameters {
              position 0.0001334620286559171
              axis -1 0 0
              anchor 1 -0.01 0.01
            }
            device [
              RotationalMotor {
                name "phalanx2"
              }
            ]
            endPoint Solid {
              translation 2.3776298041511268e-08 -0.03429576825931519 0.01964610385490715
              rotation 0.9999999999999983 1.3072143196992278e-08 5.500510072146287e-08 1.5700665379713392
              children [
                DEF PHALANX_3 HingeJoint {
                  jointParameters HingeJointParameters {
                    position 0.00015165542072754462
                    axis -1 0 0
                    anchor 1 -0.01 0.01
                  }
                  device [
                    RotationalMotor {
                      name "phalanx3"
                    }
                  ]
                  endPoint Solid {
                    translation 2.3226700118783583e-08 -0.02899865004826651 0.018902881350635593
                    rotation 0.9999999999999982 1.3072688111751324e-08 5.500516925885022e-08 1.6479983445792759
                    children [
                      DEF FORM Shape {
                        appearance PBRAppearance {
                          metalness 0
                        }
                        geometry Box {
                          size 0.02 0.02 0.03
                        }
                      }
                    ]
                    boundingObject USE FORM
                    physics Physics {
                    }
                    linearVelocity -4.7575221172612684e-08 4.1064675926695533e-07 -4.3793644396069183e-07
                    angularVelocity 6.421203519301819e-06 -2.836662662351193e-07 1.1515138860002691e-08
                  }
                }
                DEF FORM Shape {
                  appearance PBRAppearance {
                    metalness 0
                  }
                  geometry Box {
                    size 0.02 0.02 0.05
                  }
                }
              ]
              boundingObject USE FORM
              physics Physics {
              }
              linearVelocity -5.5839507691424406e-08 2.433672234422237e-07 -3.3299215953517994e-07
              angularVelocity 4.511706267840342e-06 -2.6730034486283614e-07 8.914480124286311e-09
            }
          }
          DEF FORM Shape {
            appearance PBRAppearance {
              metalness 0
            }
            geometry Box {
              size 0.02 0.02 0.05
            }
          }
        ]
        boundingObject USE FORM
        physics Physics {
        }
        linearVelocity -5.129023533867374e-08 2.804898441915574e-07 -2.2160770876132963e-07
        angularVelocity -6.151130708900491e-07 -2.2339197702354144e-07 1.9320306244101125e-09
      }
    }
    DEF PHALANX_4 HingeJoint {
      jointParameters HingeJointParameters {
        position 0.00012509455917527728
        axis -1 0 0
        anchor -0.002 0.14 0.11
      }
      device [
        RotationalMotor {
          name "phalanx4"
        }
      ]
      endPoint Solid {
        translation -0.029999999999999527 0.1330033776078592 0.1370008754506551
        rotation -1 0 0 0.00012509455865166667
        children [
          DEF PHALANX_5 HingeJoint {
            jointParameters HingeJointParameters {
              position 0.00013336386772078157
              axis -1 0 0
              anchor 1 -0.01 0.01
            }
            device [
              RotationalMotor {
                name "phalanx5"
              }
            ]
            endPoint Solid {
              translation -4.413270000558356e-07 -0.040257037186752866 0.020169894963540803
              rotation 0.9999999999803448 -2.6086542161930698e-06 -5.7013364896560334e-06 1.5700666361322733
              children [
                DEF PHALANX_6 HingeJoint {
                  jointParameters HingeJointParameters {
                    position 0.00015162906796151177
                    axis -1 0 0
                    anchor 1 -0.01 0.01
                  }
                  device [
                    RotationalMotor {
                      name "phalanx6"
                    }
                  ]
                  endPoint Solid {
                    translation 2.6018200038890882e-08 -0.03019558570214583 0.021560717652346857
                    rotation 0.9999999999999768 -5.7871563879789445e-08 2.0705991688455152e-07 1.6479983709320556
                    children [
                      DEF FORM Shape {
                        appearance PBRAppearance {
                          metalness 0
                        }
                        geometry Box {
                          size 0.02 0.02 0.034
                        }
                      }
                    ]
                    boundingObject USE FORM
                    physics Physics {
                    }
                    linearVelocity -4.811311871072411e-08 4.5475201323454667e-07 -4.798866555114012e-07
                    angularVelocity 6.881746846335231e-06 -2.879931385865644e-07 1.2137946375741045e-08
                  }
                }
                DEF FORM Shape {
                  appearance PBRAppearance {
                    metalness 0
                  }
                  geometry Box {
                    size 0.02 0.02 0.06
                  }
                }
              ]
              boundingObject USE FORM
              physics Physics {
              }
              linearVelocity -5.686773672363467e-08 2.683986785991004e-07 -3.5014794608213754e-07
              angularVelocity 4.716448329262809e-06 -2.694190638714708e-07 9.192912606905115e-09
            }
          }
          DEF FORM Shape {
            appearance PBRAppearance {
              metalness 0
            }
            geometry Box {
              size 0.02 0.02 0.06
            }
          }
        ]
        name "solid(1)"
        boundingObject USE FORM
        physics Physics {
        }
        linearVelocity -5.227072065851414e-08 3.028056901390289e-07 -2.1141140012690735e-07
        angularVelocity -1.325093991211401e-06 -2.1769123599080463e-07 9.657792717753027e-10
      }
    }
    DEF PHALANX_7 HingeJoint {
      jointParameters HingeJointParameters {
        position 0.00012510290559109016
        axis -1 0 0
        anchor -0.002 0.14 0.11
      }
      device [
        RotationalMotor {
          name "phalanx7"
        }
      ]
      endPoint Solid {
        translation -1.2750217548429532e-16 0.13251667845931203 0.13940393641536242
        rotation -1 0 0 0.0001251029044895495
        children [
          DEF PHALANX_8 HingeJoint {
            jointParameters HingeJointParameters {
              position 0.0001333864424132494
              axis -1 0 0
              anchor 1 -0.01 0.01
            }
            device [
              RotationalMotor {
                name "phalanx8"
              }
            ]
            endPoint Solid {
              translation -5.133449849648031e-07 -0.03899986039580352 0.018618366972570244
              rotation 0.9999999999732352 -3.112640633838606e-06 -6.621276441288246e-06 1.5700666135561974
              children [
                DEF PHALANX_9 HingeJoint {
                  jointParameters HingeJointParameters {
                    position 0.00015164931172084728
                    axis -1 0 0
                    anchor 1 -0.01 0.01
                  }
                  device [
                    RotationalMotor {
                      name "phalanx9"
                    }
                  ]
                  endPoint Solid {
                    translation 9.645513276979045e-10 -0.02814267215369473 0.01758771685841982
                    rotation 0.9999999999999973 4.548241573073532e-09 7.184859806853806e-08 1.6479983506882847
                    children [
                      DEF FORM Shape {
                        appearance PBRAppearance {
                          metalness 0
                        }
                        geometry Box {
                          size 0.02 0.02 0.031
                        }
                      }
                    ]
                    boundingObject USE FORM
                    physics Physics {
                    }
                    linearVelocity -4.895856049170682e-08 4.4239848057875314e-07 -4.3232417839204423e-07
                    angularVelocity 6.55456185657063e-06 -2.8492169288584435e-07 1.1690860841677562e-08
                  }
                }
                DEF FORM Shape {
                  appearance PBRAppearance {
                    metalness 0
                  }
                  geometry Box {
                    size 0.02 0.02 0.06
                  }
                }
              ]
              boundingObject USE FORM
              physics Physics {
              }
              linearVelocity -5.69964554426993e-08 2.775056467577138e-07 -3.3401788213093426e-07
              angularVelocity 4.581905267616593e-06 -2.6800156661776896e-07 9.009893019828249e-09
            }
          }
          DEF FORM Shape {
            appearance PBRAppearance {
              metalness 0
            }
            geometry Box {
              size 0.02 0.02 0.07
            }
          }
        ]
        name "solid(2)"
        boundingObject USE FORM
        physics Physics {
        }
        linearVelocity -5.280966027863184e-08 3.0412107254585807e-07 -2.0476206755556576e-07
        angularVelocity -1.2587280977377643e-06 -2.1798423878245218e-07 1.0560144200947508e-09
      }
    }
    DEF PHALANX_10 HingeJoint {
      jointParameters HingeJointParameters {
        position 0.00012509495526269454
        axis -1 0 0
        anchor -0.002 0.14 0.11
      }
      device [
        RotationalMotor {
          name "phalanx10"
        }
      ]
      endPoint Solid {
        translation 0.029999999999999936 0.13200325253142334 0.13600100055620576
        rotation -1 0 0 0.00012509495625419255
        children [
          DEF PHALANX_11 HingeJoint {
            jointParameters HingeJointParameters {
              position 0.00013340822115360092
              axis -1 0 0
              anchor 1 -0.01 0.01
            }
            device [
              RotationalMotor {
                name "phalanx11"
              }
            ]
            endPoint Solid {
              translation -4.1735499811679233e-07 -0.035398284666430635 0.019824687195680257
              rotation 0.9999999999745307 -3.3747547223423073e-06 -6.288834674181804e-06 1.570066591778815
              children [
                DEF PHALANX_12 HingeJoint {
                  jointParameters HingeJointParameters {
                    position 0.00015163606866095281
                    axis -1 0 0
                    anchor 1 -0.01 0.01
                  }
                  device [
                    RotationalMotor {
                      name "phalanx12"
                    }
                  ]
                  endPoint Solid {
                    translation 2.5116906443578557e-08 -0.028385093071097323 0.019326754674970734
                    rotation 0.9999999999999768 -5.787156334252026e-08 2.0705991775802926e-07 1.6479983639313625
                    children [
                      DEF FORM Shape {
                        appearance PBRAppearance {
                          metalness 0
                        }
                        geometry Box {
                          size 0.02 0.02 0.033
                        }
                      }
                    ]
                    boundingObject USE FORM
                    physics Physics {
                    }
                    linearVelocity -4.8504718606787265e-08 4.349696789313466e-07 -4.037995843421697e-07
                    angularVelocity 6.3644850504339904e-06 -2.8318309060139626e-07 1.1433410169698044e-08
                  }
                }
                DEF FORM Shape {
                  appearance PBRAppearance {
                    metalness 0
                  }
                  geometry Box {
                    size 0.02 0.02 0.055
                  }
                }
              ]
              boundingObject USE FORM
              physics Physics {
              }
              linearVelocity -5.656581003796479e-08 2.7515226102140195e-07 -2.988364592953487e-07
              angularVelocity 4.263861345868294e-06 -2.6515702605503685e-07 8.576854507746407e-09
            }
          }
          DEF FORM Shape {
            appearance PBRAppearance {
              metalness 0
            }
            geometry Box {
              size 0.02 0.02 0.059
            }
          }
        ]
        name "solid(3)"
        boundingObject USE FORM
        physics Physics {
        }
        linearVelocity -5.2047319143379406e-08 3.0303367231495635e-07 -1.9565377852699113e-07
        angularVelocity -1.378573642113802e-06 -2.1683630162916083e-07 8.939945906895035e-10
      }
    }
    DEF STAND Solid {
      translation 0.00011935438018114326 0.0012850773674955912 -0.0018790409268443359
      rotation -0.995258591492755 0.09726423381578422 -6.985761368042685e-05 0.012541083210237891
      children [
        DEF PALM Solid {
          translation 0 0.05 0.105
          children [
            DEF FORM Shape {
              appearance PBRAppearance {
                metalness 0
              }
              geometry Box {
                size 0.14 0.18 0.01
              }
            }
          ]
          boundingObject USE FORM
          physics Physics {
          }
        }
        DEF FORM Shape {
          appearance PBRAppearance {
            metalness 0
          }
          geometry Box {
            size 0.08 0.08 0.2
          }
        }
      ]
      name "stand"
      boundingObject USE FORM
      physics Physics {
      }
    }
  ]
  name "robo-hand"
  boundingObject USE FORM
  physics Physics {
  }
  controller "<extern>"
  linearVelocity -2.403340241745777e-08 1.3873849979263069e-07 -3.739546712813451e-08
  angularVelocity -1.2587260644402124e-06 -2.1799943018263477e-07 1.0567454266531712e-09
}
