#VRML_SIM R2025a utf8

EXTERNPROTO "https://raw.githubusercontent.com/cyberbotics/webots/R2023b/projects/objects/backgrounds/protos/TexturedBackground.proto"
EXTERNPROTO "https://raw.githubusercontent.com/cyberbotics/webots/R2023b/projects/objects/backgrounds/protos/TexturedBackgroundLight.proto"
EXTERNPROTO "https://raw.githubusercontent.com/cyberbotics/webots/R2023b/projects/objects/floors/protos/RectangleArena.proto"

WorldInfo {
}
Viewpoint {
  orientation -0.3173443774586528 0.3390561567803442 0.8856260320500539 1.5425864895378538
  position -0.30830773776967785 -1.475211120831887 1.245949630809462
}
TexturedBackground {
}
TexturedBackgroundLight {
}
RectangleArena {
}
Robot {
  translation -0.0005422801236218359 0.0033664922342425503 0.10064497042507979
  rotation 0.3033870117204683 -0.16489753696552636 -0.9384908755134634 0.0083178382419243
  children [
    DEF THUMP HingeJoint {
      jointParameters HingeJointParameters {
        position 6.215928968381861e-05
        axis 0 1 0
        anchor 0.07 0 0.12
      }
      device [
        RotationalMotor {
          name "thump"
        }
      ]
      endPoint Solid {
        translation 0.06499834330173665 0.023000000000000003 0.10300031086658581
        rotation -2.0922145915377953e-06 0.9999999999673194 7.809219254254549e-06 0.5236674664692608
        children [
          DEF PHALANX_13 HingeJoint {
            jointParameters HingeJointParameters {
              position 3.616105413200171e-05
              axis 0 1 0
              anchor 0.004 0.11 0.004
            }
            device [
              RotationalMotor {
                name "phalanx13"
              }
            ]
            endPoint Solid {
              translation -0.022399171894599904 -0.00039999999999977554 0.026900954636856586
              rotation 0.25164774253210886 -0.2595288852680236 -0.932372335169824 1.631415922054575
              children [
                DEF PHALANX_14 HingeJoint {
                  jointParameters HingeJointParameters {
                    position 0.00013301004935202187
                    axis -1 0 0
                    anchor 1 -0.01 0.01
                  }
                  device [
                    RotationalMotor {
                      name "phalanx14"
                    }
                  ]
                  endPoint Solid {
                    translation -4.123659995691753e-07 -0.036999068690819675 0.01700359120940106
                    rotation 0.99999999997445 -3.385787085549693e-06 -6.295762376480249e-06 1.648006989950649
                    children [
                      DEF PHALANX_15 HingeJoint {
                        jointParameters HingeJointParameters {
                          position -2.1095925599241821e-07
                          axis -1 0 0
                          anchor 1 -0.015 0.01
                        }
                        device [
                          RotationalMotor {
                            name "phalanx15"
                          }
                        ]
                        endPoint Solid {
                          translation 2.511690022632962e-08 -0.028275102863919335 0.023575697199494552
                          rotation 0.9999999999999769 -5.7883216188019926e-08 2.070409736830613e-07 1.6481502109592758
                          children [
                            DEF FORM Shape {
                              appearance PBRAppearance {
                                metalness 0
                              }
                              geometry Box {
                                size 0.02 0.02 0.033
                              }
                            }
                          ]
                          boundingObject USE FORM
                          physics Physics {
                          }
                        }
                      }
                      DEF FORM Shape {
                        appearance PBRAppearance {
                          metalness 0
                        }
                        geometry Box {
                          size 0.02 0.02 0.055
                        }
                      }
                    ]
                    boundingObject USE FORM
                    physics Physics {
                    }
                  }
                }
                DEF FORM Shape {
                  appearance PBRAppearance {
                    metalness 0
                  }
                  geometry Box {
                    size 0.02 0.02 0.059
                  }
                }
              ]
              name "solid(4)"
              boundingObject USE FORM
              physics Physics {
              }
            }
          }
          DEF FORM Shape {
            appearance PBRAppearance {
              metalness 0
            }
            geometry Box {
              size 0.02 0.02 0.04
            }
          }
        ]
        name "solid(5)"
        boundingObject USE FORM
        physics Physics {
        }
      }
    }
    DEF PHALANX_1 HingeJoint {
      jointParameters HingeJointParameters {
        position 0.0001250766290086247
        axis -1 0 0
        anchor -0.002 0.14 0.11
      }
      device [
        RotationalMotor {
          name "phalanx1"
        }
      ]
      endPoint Solid {
        translation -0.05999999999999999 0.13216775174711703 0.13200097980329994
        rotation -1 0 0 0.00012507662972447277
        children [
          DEF PHALANX_2 HingeJoint {
            jointParameters HingeJointParameters {
              position 0.0001334620286559171
              axis -1 0 0
              anchor 1 -0.01 0.01
            }
            device [
              RotationalMotor {
                name "phalanx2"
              }
            ]
            endPoint Solid {
              translation 2.3776298041511268e-08 -0.03429576825931519 0.01964610385490715
              rotation 0.9999999999999983 1.3072143196992278e-08 5.500510072146287e-08 1.5700665379713392
              children [
                DEF PHALANX_3 HingeJoint {
                  jointParameters HingeJointParameters {
                    position 0.00015165542072754462
                    axis -1 0 0
                    anchor 1 -0.01 0.01
                  }
                  device [
                    RotationalMotor {
                      name "phalanx3"
                    }
                  ]
                  endPoint Solid {
                    translation 2.3226700118783583e-08 -0.02899865004826651 0.018902881350635593
                    rotation 0.9999999999999982 1.3072688111751324e-08 5.500516925885022e-08 1.6479983445792759
                    children [
                      DEF FORM Shape {
                        appearance PBRAppearance {
                          metalness 0
                        }
                        geometry Box {
                          size 0.02 0.02 0.03
                        }
                      }
                    ]
                    boundingObject USE FORM
                    physics Physics {
                    }
                  }
                }
                DEF FORM Shape {
                  appearance PBRAppearance {
                    metalness 0
                  }
                  geometry Box {
                    size 0.02 0.02 0.05
                  }
                }
              ]
              boundingObject USE FORM
              physics Physics {
              }
            }
          }
          DEF FORM Shape {
            appearance PBRAppearance {
              metalness 0
            }
            geometry Box {
              size 0.02 0.02 0.05
            }
          }
        ]
        boundingObject USE FORM
        physics Physics {
        }
      }
    }
    DEF PHALANX_4 HingeJoint {
      jointParameters HingeJointParameters {
        position 0.00012509455917527728
        axis -1 0 0
        anchor -0.002 0.14 0.11
      }
      device [
        RotationalMotor {
          name "phalanx4"
        }
      ]
      endPoint Solid {
        translation -0.029999999999999527 0.1330033776078592 0.1370008754506551
        rotation -1 0 0 0.00012509455865166667
        children [
          DEF PHALANX_5 HingeJoint {
            jointParameters HingeJointParameters {
              position 0.00013336386772078157
              axis -1 0 0
              anchor 1 -0.01 0.01
            }
            device [
              RotationalMotor {
                name "phalanx5"
              }
            ]
            endPoint Solid {
              translation -4.413270000558356e-07 -0.040257037186752866 0.020169894963540803
              rotation 0.9999999999803448 -2.6086542161930698e-06 -5.7013364896560334e-06 1.5700666361322733
              children [
                DEF PHALANX_6 HingeJoint {
                  jointParameters HingeJointParameters {
                    position 0.00015162906796151177
                    axis -1 0 0
                    anchor 1 -0.01 0.01
                  }
                  device [
                    RotationalMotor {
                      name "phalanx6"
                    }
                  ]
                  endPoint Solid {
                    translation 2.6018200038890882e-08 -0.03019558570214583 0.021560717652346857
                    rotation 0.9999999999999768 -5.7871563879789445e-08 2.0705991688455152e-07 1.6479983709320556
                    children [
                      DEF FORM Shape {
                        appearance PBRAppearance {
                          metalness 0
                        }
                        geometry Box {
                          size 0.02 0.02 0.034
                        }
                      }
                    ]
                    boundingObject USE FORM
                    physics Physics {
                    }
                  }
                }
                DEF FORM Shape {
                  appearance PBRAppearance {
                    metalness 0
                  }
                  geometry Box {
                    size 0.02 0.02 0.06
                  }
                }
              ]
              boundingObject USE FORM
              physics Physics {
              }
            }
          }
          DEF FORM Shape {
            appearance PBRAppearance {
              metalness 0
            }
            geometry Box {
              size 0.02 0.02 0.06
            }
          }
        ]
        name "solid(1)"
        boundingObject USE FORM
        physics Physics {
        }
      }
    }
    DEF PHALANX_7 HingeJoint {
      jointParameters HingeJointParameters {
        position 0.00012510290559109016
        axis -1 0 0
        anchor -0.002 0.14 0.11
      }
      device [
        RotationalMotor {
          name "phalanx7"
        }
      ]
      endPoint Solid {
        translation -1.2750217548429532e-16 0.13251667845931203 0.13940393641536242
        rotation -1 0 0 0.0001251029044895495
        children [
          DEF PHALANX_8 HingeJoint {
            jointParameters HingeJointParameters {
              position 0.0001333864424132494
              axis -1 0 0
              anchor 1 -0.01 0.01
            }
            device [
              RotationalMotor {
                name "phalanx8"
              }
            ]
            endPoint Solid {
              translation -5.133449849648031e-07 -0.03899986039580352 0.018618366972570244
              rotation 0.9999999999732352 -3.112640633838606e-06 -6.621276441288246e-06 1.5700666135561974
              children [
                DEF PHALANX_9 HingeJoint {
                  jointParameters HingeJointParameters {
                    position 0.00015164931172084728
                    axis -1 0 0
                    anchor 1 -0.01 0.01
                  }
                  device [
                    RotationalMotor {
                      name "phalanx9"
                    }
                  ]
                  endPoint Solid {
                    translation 9.645513276979045e-10 -0.02814267215369473 0.01758771685841982
                    rotation 0.9999999999999973 4.548241573073532e-09 7.184859806853806e-08 1.6479983506882847
                    children [
                      DEF FORM Shape {
                        appearance PBRAppearance {
                          metalness 0
                        }
                        geometry Box {
                          size 0.02 0.02 0.031
                        }
                      }
                    ]
                    boundingObject USE FORM
                    physics Physics {
                    }
                  }
                }
                DEF FORM Shape {
                  appearance PBRAppearance {
                    metalness 0
                  }
                  geometry Box {
                    size 0.02 0.02 0.06
                  }
                }
              ]
              boundingObject USE FORM
              physics Physics {
              }
            }
          }
          DEF FORM Shape {
            appearance PBRAppearance {
              metalness 0
            }
            geometry Box {
              size 0.02 0.02 0.07
            }
          }
        ]
        name "solid(2)"
        boundingObject USE FORM
        physics Physics {
        }
      }
    }
    DEF PHALANX_10 HingeJoint {
      jointParameters HingeJointParameters {
        position 0.00012509495526269454
        axis -1 0 0
        anchor -0.002 0.14 0.11
      }
      device [
        RotationalMotor {
          name "phalanx10"
        }
      ]
      endPoint Solid {
        translation 0.029999999999999936 0.13200325253142334 0.13600100055620576
        rotation -1 0 0 0.00012509495625419255
        children [
          DEF PHALANX_11 HingeJoint {
            jointParameters HingeJointParameters {
              position 0.00013340822115360092
              axis -1 0 0
              anchor 1 -0.01 0.01
            }
            device [
              RotationalMotor {
                name "phalanx11"
              }
            ]
            endPoint Solid {
              translation -4.1735499811679233e-07 -0.035398284666430635 0.019824687195680257
              rotation 0.9999999999745307 -3.3747547223423073e-06 -6.288834674181804e-06 1.570066591778815
              children [
                DEF PHALANX_12 HingeJoint {
                  jointParameters HingeJointParameters {
                    position 0.00015163606866095281
                    axis -1 0 0
                    anchor 1 -0.01 0.01
                  }
                  device [
                    RotationalMotor {
                      name "phalanx12"
                    }
                  ]
                  endPoint Solid {
                    translation 2.5116906443578557e-08 -0.028385093071097323 0.019326754674970734
                    rotation 0.9999999999999768 -5.787156334252026e-08 2.0705991775802926e-07 1.6479983639313625
                    children [
                      DEF FORM Shape {
                        appearance PBRAppearance {
                          metalness 0
                        }
                        geometry Box {
                          size 0.02 0.02 0.033
                        }
                      }
                    ]
                    boundingObject USE FORM
                    physics Physics {
                    }
                  }
                }
                DEF FORM Shape {
                  appearance PBRAppearance {
                    metalness 0
                  }
                  geometry Box {
                    size 0.02 0.02 0.055
                  }
                }
              ]
              boundingObject USE FORM
              physics Physics {
              }
            }
          }
          DEF FORM Shape {
            appearance PBRAppearance {
              metalness 0
            }
            geometry Box {
              size 0.02 0.02 0.059
            }
          }
        ]
        name "solid(3)"
        boundingObject USE FORM
        physics Physics {
        }
      }
    }
    DEF STAND Solid {
      translation 0.00011935438018114326 0.0012850773674955912 -0.0018790409268443359
      rotation -0.995258591492755 0.09726423381578422 -6.985761368042685e-05 0.012541083210237891
      children [
        DEF PALM Solid {
          translation 0 0.05 0.105
          children [
            DEF FORM Shape {
              appearance PBRAppearance {
                metalness 0
              }
              geometry Box {
                size 0.14 0.18 0.01
              }
            }
          ]
          boundingObject USE FORM
          physics Physics {
          }
        }
        DEF FORM Shape {
          appearance PBRAppearance {
            metalness 0
          }
          geometry Box {
            size 0.08 0.08 0.2
          }
        }
      ]
      name "stand"
      boundingObject USE FORM
      physics Physics {
      }
    }
  ]
  name "robo-hand"
  boundingObject USE FORM
  physics Physics {
  }
  controller "<extern>"
}
Solid {
  translation 0.29 -0.27 0.06
  rotation -3.3905013482585576e-09 0.7071062811861719 0.7071072811865696 3.14159
  children [
    DEF BODY Shape {
      appearance PBRAppearance {
        baseColor 0.341176 0.890196 0.537255
        metalness 0
      }
      geometry Cylinder {
        height 0.1
        radius 0.025
      }
    }
  ]
  name "cylinder"
  boundingObject USE BODY
  physics Physics {
    density 10
    centerOfMass [
      0 0 0
    ]
  }
}
Solid {
  translation 0.19 0 0.11
  children [
    DEF BODY Shape {
      appearance PBRAppearance {
        baseColor 1 0.470588 0
        metalness 0
      }
      geometry Box {
        size 0.075 0.075 0.075
      }
    }
  ]
  name "box"
  boundingObject USE BODY
  physics Physics {
  }
}
Solid {
  translation -0.25 0 0.12
  children [
    DEF BODY Shape {
      appearance PBRAppearance {
        baseColor 0.207843 0.517647 0.894118
        metalness 0
      }
      geometry Sphere {
        radius 0.065
        subdivision 2
      }
    }
  ]
  name "sphere"
  boundingObject USE BODY
  physics Physics {
  }
}
